Workbook

Sheet RSEA Safety Signs
A1: RSEA Code | B1: Product / Sign | C1: Price (AUD inc GST) | D1: Source
A2: 1046218 | B2: Security Notice This Area Is Under 24 Hours W'Picto Poly 450x300 SW023LSP | C2: 37.99 | D2: https://www.rsea.com.au/road-safety/road-safety-signage
A3: 114090 | B3: Security Sign This Area Is Under 24 Hour Surv Metal 450x300 SW023LSM | C3: 42.99 | D3: https://www.rsea.com.au/road-safety/road-safety-signage
A4: 201032 | B4: Uniform Safety Flat Plate Swing Stand Reduce Speed Metal SG519-ALUM | C4: 134.99 | D4: https://www.rsea.com.au/road-safety/road-safety-signage
A5: 201033 | B5: Unifrom Safety Sign Flate Plat Swing Stand End Roadwork Metal SG501-ALUM | C5: 167.99 | D5: https://www.rsea.com.au/road-safety/road-safety-signage
A6: 60268 | B6: Stop 600mm Octagonal Metal Traffic Sign R1-1A-1X | C6: 147.99 | D6: https://www.rsea.com.au/road-safety/road-safety-signage
A7: 60273 | B7: Give Way 750mm Triangle Metal Traffic Sign R1-2A | C7: 167.99 | D7: https://www.rsea.com.au/road-safety/road-safety-signage
A8: 60290 | B8: Keep Left Arrow 450x600mm Metal Traffic Sign R2-3AL | C8: 142.99 | D8: https://www.rsea.com.au/road-safety/road-safety-signage
A9: 60314 | B9: Lime Green Pedestrian Crossing Sign 600mm | C9: 157.99 | D9: https://www.rsea.com.au/road-safety/road-safety-signage
A10: 60495 | B10: Multi-Message 1200x900mm Standard Black Frame MMF | C10: 132.99 | D10: https://www.rsea.com.au/road-safety/road-safety-signage
A11: 60496 | B11: Bi-Pod Folding Legs (Pair) FBL1 MMBL | C11: 57.99 | D11: https://www.rsea.com.au/road-safety/road-safety-signage
A12: 60515 | B12: Sign Post Wizard Socket 400-450mm | C12: 52.99 | D12: https://www.rsea.com.au/road-safety/road-safety-signage
A13: 60520 | B13: De Neefe Sign Post Gibb Key - PW-GIB-KEY RK | C13: 9.99 | D13: https://www.rsea.com.au/road-safety/road-safety-signage
... A85: 869327 | B85: Security Sign Elec Surveillance Protects Property SW022LSM Metal450x300 | C85: 44.99 | D85: https://www.rsea.com.au/road-safety/road-safety-signage
A86: 869339 | B86: Reverse Parking Only 450x300mm Metal Traffic Sign TC454LSM | C86: 44.99 | D86: https://www.rsea.com.au/road-safety/road-safety-signage
A87: 869668 | B87: Traffic Sign 20kmh Speed Limit CL1 Aluminium 600x450mm TC462C1 | C87: 142.99 | D87: https://www.rsea.com.au/road-safety/road-safety-signage
A88: 869714 | B88: Pedestrians Watch Your Step 900x600mm Flat Plate Sign SG503-ALUM | C88: 167.99 | D88: https://www.rsea.com.au/road-safety/road-safety-signage
A89: 869716 | B89: Symbolic Worker 900x600mm Flat Plate Sign SG516-ALUM | C89: 167.99 | D89: https://www.rsea.com.au/road-safety/road-safety-signage
A90: 869718 | B90: Use Other Footpath 900x600mm Flat Plate Sign SG504-ALUM | C90: 167.99 | D90: https://www.rsea.com.au/road-safety/road-safety-signage
A91: 869719 | B91: UNISAF Flat Plate suite Swing Stand - Pedestrians Right Arrow 900x600 - SG515-ALUM | C91: 167.99 | D91: https://www.rsea.com.au/road-safety/road-safety-signage
A92: 869720 | B92: UNISAF Flat Plate suit Swing Stand Pedestrians Left Arrow 900x600mm - SG514-ALUM | C92: 167.99 | D92: https://www.rsea.com.au/road-safety/road-safety-signage
A93: 869721 | B93: Symbolic Chevron 600x600mm Flat Plate Sign SG210-ALUM | C93: 122.99 | D93: https://www.rsea.com.au/road-safety/road-safety-signage

Sheet Notes
A1: RSEA Road Safety Signage | B1: Catalogue extract
A2: Source | B2: https://www.rsea.com.au/road-safety/road-safety-signage
A3: Captured | B3: 8 September 2026
A4: Note | B4: Prices shown are displayed RSEA prices including GST and may change.

Sheet 1.6 AL ON WEBSITE
A1: 114090 | B1: Security Sign This Area Is Under 24 Hour Surv Metal 450x300 SW023LSM | C1: 42.99 | D1: 16.71 | E1: 16.93275 | F1: Site/Warehouse safety sign
A2: 201032 | B2: Uniform Safety Flat Plate Swing Stand Reduce Speed Metal SG519-ALUM | C2: 134.99 | D2: 66.83 | F2: Traffic control temp signage assuming this is 900x600 no sizes provided, more used for gardnening or side road works. Swing stand holes required
A3: 201033 | B3: Unifrom Safety Sign Flate Plat Swing Stand End Roadwork Metal SG501-ALUM | C3: 167.99 | D3: 44.55 | F3: Traffic control temp signage assuming this is 900x600 no sizes provided, more used for gardnening or side road works. Swing stand holes required
A4: 60268 | B4: Stop 600mm Octagonal Metal Traffic Sign R1-1A-1X | C4: 147.99 | D4: 44.55 | E4: 45.144 | F4: Traffic signage, STOP sign, only sold in one size at RSEA, comes in 3 different standard sizes.
A5: 60273 | B5: Give Way 750mm Triangle Metal Traffic Sign R1-2A | C5: 167.99 | D5: 69.61 | E5: 70.538125 | F5: Traffic signage, GIVE WAY sign, only sold in one size at RSEA comes in 4 different standard sizes
A6: 60290 | B6: Keep Left Arrow 450x600mm Metal Traffic Sign R2-3AL | C6: 142.99 | D6: 33.41 | E6: 33.8555 | F6: Traffic signage, KEEP LEFT sign, only sold in one size at RSEA, comes in 3 different standard sizes
A7: 60314 | B7: Lime Green Pedestrian Crossing Sign 600mm | C7: 157.99 | D7: 44.55 | E7: 45.144 | F7: Traffic signage, PEDESTRIAN CROSSING sign, only sold in one size at RSEA, comes in 3 standard sizes.
A8: 61041 | B8: Regulatory Sign Speed Restriction 10km 450x600mm Metal | C8: 142.99 | D8: 33.41 | E8: 33.8555 | F8: Traffic signage, 10KM SPEED sign, only sold in one size at RSEA. Comes in 4 standard sizes
A9: 61138 | B9: Regulatory Sign No Entry Metal 450x450 R2-4A-1 | C9: 112.99 | D9: 25.06 | E9: 25.394125 | F9: Traffic signage, NO ENTRY sign, only one size sold at RSEA. Comes in 5 standard sizes.
A10: 685224 | B10: 216MM 25D-LM Sign Danger Forklift Operating Area Metal 300x225 | C10: 32.99 | D10: 8.35 | E10: 8.461375 | F10: Site/Warehouse safety sign
A11: 685264 | B11: Danger Confined Space Entry By Permit Metal Sign 450x300mm | C11: 44.99 | D11: 15.59 | E11: 15.81275 | F11: Site/Warehouse safety sign
A12: 685642 | B12: First Aid Emergency Eye Wash Metal Sign 300x225mm 506MM | C12: 32.99 | D12: 8.35 | E12: 8.461375 | F12: Site/Warehouse safety sign
A13: 685976 | B13: Speed 5km 600x400mm Metal Traffic Sign TC409LM | C13: 69.99 | D13: 29.7 | E13: 30.1455 | F13: Site/Warehouse safety sign - Not to spec to be a traffic sign, incorrect sizes, used for warehouses or entrances into warehouse parking.
A14: 685980 | B14: Speed 10km 600x400mm Metal Traffic Sign TC410LM | C14: 84.99 | D14: 29.7 | E14: 30.1455 | F14: Site/Warehouse safety sign - Not to spec to be a traffic sign, incorrect sizes, used for warehouses or entrances into warehouse parking.
A15: 686188 | B15: Disabled Parking 450x300mm Metal Traffic Sign TC420LSM | C15: 44.99 | D15: 16.71 | E15: 16.93275 | F15: Private car park signage
A16: 686503 | B16: Traffic Sign No Parking Metal 600x450 TC426LM | C16: 64.99 | D16: 33.41 | E16: 33.8555 | F16: Private car park signage
A17: 686829 | B17: No Standing Anytime Double Arrow Symbolic Metal 300 x 450mm | C17: 44.99 | D17: 11.81 | E17: 12.03275 | F17: Private car park signage
A18: 712752 | B18: 840307 TC426LSM Sign No Parking Metal 450x300 | C18: 49.99 | D18: 11.81 | E18: 12.03275 | F18: Private car park signage
A19: 713252 | B19: 841090 415MM 112P-LM Sign Prohibition No Smoking In This Area Metal 300x225 | C19: 37.99 | D19: 5.9 | E19: 6.011375 | F19: Site/warehouse/office space signage
A20: 716586 | B20: 832221 892LSM Restricted Area Auth Personnel Only Metal 450x300 | C20: 49.99 | D20: 11.81 | E20: 12.03275 | F20: Site/warehouse/office space signage
A21: 869327 | B21: Security Sign Elec Surveillance Protects Property SW022LSM Metal450x300 | C21: 44.99 | D21: 11.81 | E21: 12.03275 | F21: Site/warehouse/office space signage
A22: 869339 | B22: Reverse Parking Only 450x300mm Metal Traffic Sign TC454LSM | C22: 44.99 | D22: 11.81 | E22: 12.03275 | F22: Private car park signage
A23: 869206 | B23: Regulatory Sign Speed 5km CL1 Aluminium 600x450 TC409C1 | C23: 142.99 | D23: 33.41 | E23: 33.8555 | F23: Traffic signage, 5KM SPEED sign, RSEA stock one size comes in 4 standard sizes
A24: 869668 | B24: Traffic Sign 20kmh Speed Limit CL1 Aluminium 600x450mm TC462C1 | C24: 142.99 | D24: 33.41 | E24: 33.8555 | F24: Traffic signage, 20KM SPEED sign, RSEA stock one size comes in 4 standard sizes

Sheet CORFLUTE 6MM ON WEBSITE
A1: 60837 | B1: 6mm Corflute- 1200x300mm Class 1 Reflective On Side Road (B/Y) | C1: 57.99 | D1: 13.07
A2: 60846 | B2: UNISAF Corflute Multi Message Sign Blank Yellow T9-91 | C2: 44.99 | D2: assuming 600x600? $13.07
A3: 60877 | B3: Symbolic Worker 600x600mm Multi-Message Sign CT284-40FR | C3: 52.99 | D3: 16.04
A4: 60885 | B4: Speed 60km 600x600mm Multi-Message Sign TC210 | C4: 57.99 | D4: 16.04
A5: 60886 | B5: Speed 40km 600x600mm Multi-Message Sign CT284-24H | C5: 57.99 | D5: 16.04
A6: 60887 | B6: Prepare To Stop 1200x300mm Multi-Message Sign CT284-15H | C6: 57.99 | D6: 16.04
A7: 60895 | B7: Roadwork Ahead 1200x300mm Multi-Message Sign TC221 | C7: 57.99 | D7: 13.07
A8: 60896 | B8: Drive Safety 1200x300mm Multi-Message Sign CT284-18H | C8: 59.99 | D8: 16.04
A9: 60898 | B9: Road Closed 1200x300mm Multi-Message Sign CT284-49H | C9: 57.99 | D9: 13.07
A10: 60991 | B10: Detour Left Arrow 1200x300mm Multi-Message Sign TC230 | C10: 57.99 | D10: 13.07
A11: 60992 | B11: Detour Right Arrow 1200x300mm Multi-Message Sign TC231 | C11: 57.99 | D11: 13.07
A12: 61021 | B12: Pedestrians Right Arrow 1200x300mm Multi-Message Sign CT284-T8-2R38 | C12: 57.99 | D12: 13.07
A13: 61022 | B13: Pedestrians Left Arrow 1200x300mm Multi-Message Sign CT284-T8-2L38 | C13: 57.99 | D13: 13.07

Sheet POLY ON WEBSITE
A1: 1046218 | B1: Security Notice This Area Is Under 24 Hours W'Picto Poly 450x300 SW023LSP | C1: 37.99 | D1: 5.35 | F1: QOUTED ALL ON NON REFLECTIVE 2105, NO INFO ONLINE REGARDING REFLECTIVITY.
A2: 685029 | B2: 103MP 14M-LP Sign Eye Protection Must Be Worn Poly 300x225 | C2: 24.99 | D2: 2.67
A3: 685151 | B3: Building Site Sign All Visitors Must Report To Site Office Poly 600x450 116LP | C3: 44.99 | D3: 10.69
A4: 685177 | B4: 204MP 55D-LP Sign Danger No Smoking No Naked Flame Poly 300x225 | C4: 24.99 | D4: 2.67
A5: 685231 | B5: 217LP 127D-NP Sign Danger Construction Site Do Not Enter Poly 600x400 | C5: 44.99 | D5: 9.5
A6: 685255 | B6: Danger Sign Demolition Work In Progress Poly 600x450 223LP | C6: 44.99 | D6: 10.69
A7: 685265 | B7: 225LSP 96D-MP Sign Danger Confined Space Entry By Permit Poly 450x300 | C7: 32.99 | D7: 5.35
A8: 685612 | B8: 501LSP 20E-MP 835331 Sign First Aid Poly 450x300 | C8: 49.99 | D8: 5.35
A9: 685622 | B9: 502MP 75E-LP Sign First Aid Station Poly 300x225 | C9: 27.99 | D9: 2.67
A10: 685659 | B10: 509LP 88E-NP Sign Emergency Assembly AREA Poly 600x400 | C10: 44.99 | D10: 9.5
A11: 685727 | B11: Fire Equipment Sign Fire Extinguisher Off The Wall Poly 225x225 705OWP | C11: 49.99 | D11: 2
A12: 685735 | B12: 707MP 57E-LP Sign Fire Hose Reel & Picto Poly 300x225 | C12: 32.99 | D12: 2.67
A13: 685925 | B13: 952OLP 293-KP Sign Arrow Poly 450x200 | C13: 37.99 | D13: 4.01
... A19: 712169 | B19: Danger Workers Above Poly Sign 600x450mm | C19: 49.99 | D19: 10.69
A20: 715740 | B20: 432MP 840223 153P-LP Sign Prohibition No Pedestrian Access Poly 300x225 | C20: 32.99 | D20: =D18*1.65 -> 3.201
A21: 715804 | B21: General Sign Lunch Room Poly 450x300 944LSP | C21: 32.99 | D21: 5.35
A22: 717991 | B22: Danger Sign Flammable Material Storage Area Poly 300x225 256MP | C22: 32.99 | D22: 2.67
A23: 869094 | B23: Danger Sign Overhead Power Lines Corflute 600x450 265LC | C23: 32.99 | D23: 10.69

Sheet RSEA vs Quoted Comparison
A1: RSEA Website Prices vs Our Quoted Prices
A2: Methodology: RSEA's website prices (Tab "RSEA Safety Signs") are displayed INCLUDING GST (per the Notes tab). Our quoted prices in Tabs 3-5 are EX GST trade quotes. To compare on a like-for-like basis, RSEA's price is also shown ex GST (÷1.1) alongside an inc-GST version of our quote (×1.1), so both an ex-GST and an inc-GST comparison are available.
A3: Source data captured 8 September 2026 from rsea.com.au/road-safety/road-safety-signage (per Notes tab). Re-verified live against rsea.com.au on 8 October 2026 for all 60 quoted items below — all 60 matched the live website price exactly, no changes found.
A5: Category | B5: RSEA Code | C5: Product / Sign | D5: RSEA Website Price (inc GST) | E5: RSEA Website Price (ex GST) | F5: Our Quoted Price (ex GST) | G5: Our Quoted Price (inc GST) | H5: Our Quoted Price - 1220 Stock (ex GST) | I5: Our Quoted Price - 1220 Stock (inc GST) | J5: Difference, ex GST (RSEA − Ours) | K5: RSEA Price as % above Our Quote | L5: Notes
A6: 1.6mm Aluminium | B6: ='1.6 AL ON WEBSITE'!A1 -> 114090 | C6: ='1.6 AL ON WEBSITE'!B1 -> Security Sign This Area Is Under 24 Hour Surv Metal 450x300 SW023LSM | D6: ='1.6 AL ON WEBSITE'!C1 -> 42.99 | E6: =D6/1.1 -> 39.081818 | F6: ='1.6 AL ON WEBSITE'!D1 -> 16.71 | G6: =F6*1.1 -> 18.381 | H6: =IF('1.6 AL ON WEBSITE'!E1="","",'1.6 AL ON WEBSITE'!E1) -> 16.93275 | I6: =IF(H6="","",H6*1.1) -> 18.626025 | J6: =E6-F6 -> 22.371818 | K6: =IFERROR(E6/F6-1,"") -> 1.3388281 | L6: =IF('1.6 AL ON WEBSITE'!F1="","",'1.6 AL ON WEBSITE'!F1) -> Site/Warehouse safety sign
A7: 1.6mm Aluminium | B7: ='1.6 AL ON WEBSITE'!A2 -> 201032 | C7: ='1.6 AL ON WEBSITE'!B2 -> Uniform Safety Flat Plate Swing Stand Reduce Speed Metal SG519-ALUM | D7: ='1.6 AL ON WEBSITE'!C2 -> 134.99 | E7: =D7/1.1 -> 122.71818 | F7: ='1.6 AL ON WEBSITE'!D2 -> 66.83 | G7: =F7*1.1 -> 73.513 | H7: =IF('1.6 AL ON WEBSITE'!E2="","",'1.6 AL ON WEBSITE'!E2) | I7: =IF(H7="","",H7*1.1) | J7: =E7-F7 -> 55.888182 | K7: =IFERROR(E7/F7-1,"") -> 0.83627386 | L7: =IF('1.6 AL ON WEBSITE'!F2="","",'1.6 AL ON WEBSITE'!F2) -> Traffic control temp signage assuming this is 900x600 no sizes provided, more used for gardnening or side road works. Swing stand holes required
A8: 1.6mm Aluminium | B8: ='1.6 AL ON WEBSITE'!A3 -> 201033 | C8: ='1.6 AL ON WEBSITE'!B3 -> Unifrom Safety Sign Flate Plat Swing Stand End Roadwork Metal SG501-ALUM | D8: ='1.6 AL ON WEBSITE'!C3 -> 167.99 | E8: =D8/1.1 -> 152.71818 | F8: ='1.6 AL ON WEBSITE'!D3 -> 44.55 | G8: =F8*1.1 -> 49.005 | H8: =IF('1.6 AL ON WEBSITE'!E3="","",'1.6 AL ON WEBSITE'!E3) | I8: =IF(H8="","",H8*1.1) | J8: =E8-F8 -> 108.16818 | K8: =IFERROR(E8/F8-1,"") -> 2.4280175 | L8: =IF('1.6 AL ON WEBSITE'!F3="","",'1.6 AL ON WEBSITE'!F3) -> Traffic control temp signage assuming this is 900x600 no sizes provided, more used for gardnening or side road works. Swing stand holes required
A9: 1.6mm Aluminium | B9: ='1.6 AL ON WEBSITE'!A4 -> 60268 | C9: ='1.6 AL ON WEBSITE'!B4 -> Stop 600mm Octagonal Metal Traffic Sign R1-1A-1X | D9: ='1.6 AL ON WEBSITE'!C4 -> 147.99 | E9: =D9/1.1 -> 134.53636 | F9: ='1.6 AL ON WEBSITE'!D4 -> 44.55 | G9: =F9*1.1 -> 49.005 | H9: =IF('1.6 AL ON WEBSITE'!E4="","",'1.6 AL ON WEBSITE'!E4) -> 45.144 | I9: =IF(H9="","",H9*1.1) -> 49.6584 | J9: =E9-F9 -> 89.986364 | K9: =IFERROR(E9/F9-1,"") -> 2.0198959 | L9: =IF('1.6 AL ON WEBSITE'!F4="","",'1.6 AL ON WEBSITE'!F4) -> Traffic signage, STOP sign, only sold in one size at RSEA, comes in 3 different standard sizes.
A10: 1.6mm Aluminium | B10: ='1.6 AL ON WEBSITE'!A5 -> 60273 | C10: ='1.6 AL ON WEBSITE'!B5 -> Give Way 750mm Triangle Metal Traffic Sign R1-2A | D10: ='1.6 AL ON WEBSITE'!C5 -> 167.99 | E10: =D10/1.1 -> 152.71818 | F10: ='1.6 AL ON WEBSITE'!D5 -> 69.61 | G10: =F10*1.1 -> 76.571 | H10: =IF('1.6 AL ON WEBSITE'!E5="","",'1.6 AL ON WEBSITE'!E5) -> 70.538125 | I10: =IF(H10="","",H10*1.1) -> 77.591938 | J10: =E10-F10 -> 83.108182 | K10: =IFERROR(E10/F10-1,"") -> 1.1939115 | L10: =IF('1.6 AL ON WEBSITE'!F5="","",'1.6 AL ON WEBSITE'!F5) -> Traffic signage, GIVE WAY sign, only sold in one size at RSEA comes in 4 different standard sizes
A11: 1.6mm Aluminium | B11: ='1.6 AL ON WEBSITE'!A6 -> 60290 | C11: ='1.6 AL ON WEBSITE'!B6 -> Keep Left Arrow 450x600mm Metal Traffic Sign R2-3AL | D11: ='1.6 AL ON WEBSITE'!C6 -> 142.99 | E11: =D11/1.1 -> 129.99091 | F11: ='1.6 AL ON WEBSITE'!D6 -> 33.41 | G11: =F11*1.1 -> 36.751 | H11: =IF('1.6 AL ON WEBSITE'!E6="","",'1.6 AL ON WEBSITE'!E6) -> 33.8555 | I11: =IF(H11="","",H11*1.1) -> 37.24105 | J11: =E11-F11 -> 96.580909 | K11: =IFERROR(E11/F11-1,"") -> 2.8907785 | L11: =IF('1.6 AL ON WEBSITE'!F6="","",'1.6 AL ON WEBSITE'!F6) -> Traffic signage, KEEP LEFT sign, only sold in one size at RSEA, comes in 3 different standard sizes
A12: 1.6mm Aluminium | B12: ='1.6 AL ON WEBSITE'!A7 -> 60314 | C12: ='1.6 AL ON WEBSITE'!B7 -> Lime Green Pedestrian Crossing Sign 600mm | D12: ='1.6 AL ON WEBSITE'!C7 -> 157.99 | E12: =D12/1.1 -> 143.62727 | F12: ='1.6 AL ON WEBSITE'!D7 -> 44.55 | G12: =F12*1.1 -> 49.005 | H12: =IF('1.6 AL ON WEBSITE'!E7="","",'1.6 AL ON WEBSITE'!E7) -> 45.144 | I12: =IF(H12="","",H12*1.1) -> 49.6584 | J12: =E12-F12 -> 99.077273 | K12: =IFERROR(E12/F12-1,"") -> 2.2239567 | L12: =IF('1.6 AL ON WEBSITE'!F7="","",'1.6 AL ON WEBSITE'!F7) -> Traffic signage, PEDESTRIAN CROSSING sign, only sold in one size at RSEA, comes in 3 standard sizes.
A13: 1.6mm Aluminium | B13: ='1.6 AL ON WEBSITE'!A8 -> 61041 | C13: ='1.6 AL ON WEBSITE'!B8 -> Regulatory Sign Speed Restriction 10km 450x600mm Metal | D13: ='1.6 AL ON WEBSITE'!C8 -> 142.99 | E13: =D13/1.1 -> 129.99091 | F13: ='1.6 AL ON WEBSITE'!D8 -> 33.41 | G13: =F13*1.1 -> 36.751 | H13: =IF('1.6 AL ON WEBSITE'!E8="","",'1.6 AL ON WEBSITE'!E8) -> 33.8555 | I13: =IF(H13="","",H13*1.1) -> 37.24105 | J13: =E13-F13 -> 96.580909 | K13: =IFERROR(E13/F13-1,"") -> 2.8907785 | L13: =IF('1.6 AL ON WEBSITE'!F8="","",'1.6 AL ON WEBSITE'!F8) -> Traffic signage, 10KM SPEED sign, only sold in one size at RSEA. Comes in 4 standard sizes
A14: 1.6mm Aluminium | B14: ='1.6 AL ON WEBSITE'!A9 -> 61138 | C14: ='1.6 AL ON WEBSITE'!B9 -> Regulatory Sign No Entry Metal 450x450 R2-4A-1 | D14: ='1.6 AL ON WEBSITE'!C9 -> 112.99 | E14: =D14/1.1 -> 102.71818 | F14: ='1.6 AL ON WEBSITE'!D9 -> 25.06 | G14: =F14*1.1 -> 27.566 | H14: =IF('1.6 AL ON WEBSITE'!E9="","",'1.6 AL ON WEBSITE'!E9) -> 25.394125 | I14: =IF(H14="","",H14*1.1) -> 27.933537 | J14: =E14-F14 -> 77.658182 | K14: =IFERROR(E14/F14-1,"") -> 3.0988899 | L14: =IF('1.6 AL ON WEBSITE'!F9="","",'1.6 AL ON WEBSITE'!F9) -> Traffic signage, NO ENTRY sign, only one size sold at RSEA. Comes in 5 standard sizes.
A15: 1.6mm Aluminium | B15: ='1.6 AL ON WEBSITE'!A10 -> 685224 | C15: ='1.6 AL ON WEBSITE'!B10 -> 216MM 25D-LM Sign Danger Forklift Operating Area Metal 300x225 | D15: ='1.6 AL ON WEBSITE'!C10 -> 32.99 | E15: =D15/1.1 -> 29.990909 | F15: ='1.6 AL ON WEBSITE'!D10 -> 8.35 | G15: =F15*1.1 -> 9.185 | H15: =IF('1.6 AL ON WEBSITE'!E10="","",'1.6 AL ON WEBSITE'!E10) -> 8.461375 | I15: =IF(H15="","",H15*1.1) -> 9.3075125 | J15: =E15-F15 -> 21.640909 | K15: =IFERROR(E15/F15-1,"") -> 2.5917256 | L15: =IF('1.6 AL ON WEBSITE'!F10="","",'1.6 AL ON WEBSITE'!F10) -> Site/Warehouse safety sign
A16: 1.6mm Aluminium | B16: ='1.6 AL ON WEBSITE'!A11 -> 685264 | C16: ='1.6 AL ON WEBSITE'!B11 -> Danger Confined Space Entry By Permit Metal Sign 450x300mm | D16: ='1.6 AL ON WEBSITE'!C11 -> 44.99 | E16: =D16/1.1 -> 40.9 | F16: ='1.6 AL ON WEBSITE'!D11 -> 15.59 | G16: =F16*1.1 -> 17.149 | H16: =IF('1.6 AL ON WEBSITE'!E11="","",'1.6 AL ON WEBSITE'!E11) -> 15.81275 | I16: =IF(H16="","",H16*1.1) -> 17.394025 | J16: =E16-F16 -> 25.31 | K16: =IFERROR(E16/F16-1,"") -> 1.6234766 | L16: =IF('1.6 AL ON WEBSITE'!F11="","",'1.6 AL ON WEBSITE'!F11) -> Site/Warehouse safety sign
A17: 1.6mm Aluminium | B17: ='1.6 AL ON WEBSITE'!A12 -> 685642 | C17: ='1.6 AL ON WEBSITE'!B12 -> First Aid Emergency Eye Wash Metal Sign 300x225mm 506MM | D17: ='1.6 AL ON WEBSITE'!C12 -> 32.99 | E17: =D17/1.1 -> 29.990909 | F17: ='1.6 AL ON WEBSITE'!D12 -> 8.35 | G17: =F17*1.1 -> 9.185 | H17: =IF('1.6 AL ON WEBSITE'!E12="","",'1.6 AL ON WEBSITE'!E12) -> 8.461375 | I17: =IF(H17="","",H17*1.1) -> 9.3075125 | J17: =E17-F17 -> 21.640909 | K17: =IFERROR(E17/F17-1,"") -> 2.5917256 | L17: =IF('1.6 AL ON WEBSITE'!F12="","",'1.6 AL ON WEBSITE'!F12) -> Site/Warehouse safety sign
... A29: 1.6mm Aluminium | B29: ='1.6 AL ON WEBSITE'!A24 -> 869668 | C29: ='1.6 AL ON WEBSITE'!B24 -> Traffic Sign 20kmh Speed Limit CL1 Aluminium 600x450mm TC462C1 | D29: ='1.6 AL ON WEBSITE'!C24 -> 142.99 | E29: =D29/1.1 -> 129.99091 | F29: ='1.6 AL ON WEBSITE'!D24 -> 33.41 | G29: =F29*1.1 -> 36.751 | H29: =IF('1.6 AL ON WEBSITE'!E24="","",'1.6 AL ON WEBSITE'!E24) -> 33.8555 | I29: =IF(H29="","",H29*1.1) -> 37.24105 | J29: =E29-F29 -> 96.580909 | K29: =IFERROR(E29/F29-1,"") -> 2.8907785 | L29: =IF('1.6 AL ON WEBSITE'!F24="","",'1.6 AL ON WEBSITE'!F24) -> Traffic signage, 20KM SPEED sign, RSEA stock one size comes in 4 standard sizes
A30: 6mm Corflute | B30: ='CORFLUTE 6MM ON WEBSITE'!A1 -> 60837 | C30: ='CORFLUTE 6MM ON WEBSITE'!B1 -> 6mm Corflute- 1200x300mm Class 1 Reflective On Side Road (B/Y) | D30: ='CORFLUTE 6MM ON WEBSITE'!C1 -> 57.99 | E30: =D30/1.1 -> 52.718182 | F30: ='CORFLUTE 6MM ON WEBSITE'!D1 -> 13.07 | G30: =F30*1.1 -> 14.377 | J30: =E30-F30 -> 39.648182 | K30: =IFERROR(E30/F30-1,"") -> 3.0335258
A31: 6mm Corflute | B31: ='CORFLUTE 6MM ON WEBSITE'!A2 -> 60846 | C31: ='CORFLUTE 6MM ON WEBSITE'!B2 -> UNISAF Corflute Multi Message Sign Blank Yellow T9-91 | D31: ='CORFLUTE 6MM ON WEBSITE'!C2 -> 44.99 | E31: =D31/1.1 -> 40.9 | F31: 13.07 | G31: =F31*1.1 -> 14.377 | J31: =E31-F31 -> 27.83 | K31: =IFERROR(E31/F31-1,"") -> 2.1293037 | L31: Source tab D2 held text "assuming 600x600? $13.07" - CONFIRMED 8 Oct 2026: RSEA's own product page lists this item as 600x600mm Corflute, so Jess's size assumption was correct ($13.07 used as the quote).
A32: 6mm Corflute | B32: ='CORFLUTE 6MM ON WEBSITE'!A3 -> 60877 | C32: ='CORFLUTE 6MM ON WEBSITE'!B3 -> Symbolic Worker 600x600mm Multi-Message Sign CT284-40FR | D32: ='CORFLUTE 6MM ON WEBSITE'!C3 -> 52.99 | E32: =D32/1.1 -> 48.172727 | F32: ='CORFLUTE 6MM ON WEBSITE'!D3 -> 16.04 | G32: =F32*1.1 -> 17.644 | J32: =E32-F32 -> 32.132727 | K32: =IFERROR(E32/F32-1,"") -> 2.0032872
A33: 6mm Corflute | B33: ='CORFLUTE 6MM ON WEBSITE'!A4 -> 60885 | C33: ='CORFLUTE 6MM ON WEBSITE'!B4 -> Speed 60km 600x600mm Multi-Message Sign TC210 | D33: ='CORFLUTE 6MM ON WEBSITE'!C4 -> 57.99 | E33: =D33/1.1 -> 52.718182 | F33: ='CORFLUTE 6MM ON WEBSITE'!D4 -> 16.04 | G33: =F33*1.1 -> 17.644 | J33: =E33-F33 -> 36.678182 | K33: =IFERROR(E33/F33-1,"") -> 2.2866697
A34: 6mm Corflute | B34: ='CORFLUTE 6MM ON WEBSITE'!A5 -> 60886 | C34: ='CORFLUTE 6MM ON WEBSITE'!B5 -> Speed 40km 600x600mm Multi-Message Sign CT284-24H | D34: ='CORFLUTE 6MM ON WEBSITE'!C5 -> 57.99 | E34: =D34/1.1 -> 52.718182 | F34: ='CORFLUTE 6MM ON WEBSITE'!D5 -> 16.04 | G34: =F34*1.1 -> 17.644 | J34: =E34-F34 -> 36.678182 | K34: =IFERROR(E34/F34-1,"") -> 2.2866697
A35: 6mm Corflute | B35: ='CORFLUTE 6MM ON WEBSITE'!A6 -> 60887 | C35: ='CORFLUTE 6MM ON WEBSITE'!B6 -> Prepare To Stop 1200x300mm Multi-Message Sign CT284-15H | D35: ='CORFLUTE 6MM ON WEBSITE'!C6 -> 57.99 | E35: =D35/1.1 -> 52.718182 | F35: ='CORFLUTE 6MM ON WEBSITE'!D6 -> 16.04 | G35: =F35*1.1 -> 17.644 | J35: =E35-F35 -> 36.678182 | K35: =IFERROR(E35/F35-1,"") -> 2.2866697
A36: 6mm Corflute | B36: ='CORFLUTE 6MM ON WEBSITE'!A7 -> 60895 | C36: ='CORFLUTE 6MM ON WEBSITE'!B7 -> Roadwork Ahead 1200x300mm Multi-Message Sign TC221 | D36: ='CORFLUTE 6MM ON WEBSITE'!C7 -> 57.99 | E36: =D36/1.1 -> 52.718182 | F36: ='CORFLUTE 6MM ON WEBSITE'!D7 -> 13.07 | G36: =F36*1.1 -> 14.377 | J36: =E36-F36 -> 39.648182 | K36: =IFERROR(E36/F36-1,"") -> 3.0335258
A37: 6mm Corflute | B37: ='CORFLUTE 6MM ON WEBSITE'!A8 -> 60896 | C37: ='CORFLUTE 6MM ON WEBSITE'!B8 -> Drive Safety 1200x300mm Multi-Message Sign CT284-18H | D37: ='CORFLUTE 6MM ON WEBSITE'!C8 -> 59.99 | E37: =D37/1.1 -> 54.536364 | F37: ='CORFLUTE 6MM ON WEBSITE'!D8 -> 16.04 | G37: =F37*1.1 -> 17.644 | J37: =E37-F37 -> 38.496364 | K37: =IFERROR(E37/F37-1,"") -> 2.4000227
A38: 6mm Corflute | B38: ='CORFLUTE 6MM ON WEBSITE'!A9 -> 60898 | C38: ='CORFLUTE 6MM ON WEBSITE'!B9 -> Road Closed 1200x300mm Multi-Message Sign CT284-49H | D38: ='CORFLUTE 6MM ON WEBSITE'!C9 -> 57.99 | E38: =D38/1.1 -> 52.718182 | F38: ='CORFLUTE 6MM ON WEBSITE'!D9 -> 13.07 | G38: =F38*1.1 -> 14.377 | J38: =E38-F38 -> 39.648182 | K38: =IFERROR(E38/F38-1,"") -> 3.0335258
A39: 6mm Corflute | B39: ='CORFLUTE 6MM ON WEBSITE'!A10 -> 60991 | C39: ='CORFLUTE 6MM ON WEBSITE'!B10 -> Detour Left Arrow 1200x300mm Multi-Message Sign TC230 | D39: ='CORFLUTE 6MM ON WEBSITE'!C10 -> 57.99 | E39: =D39/1.1 -> 52.718182 | F39: ='CORFLUTE 6MM ON WEBSITE'!D10 -> 13.07 | G39: =F39*1.1 -> 14.377 | J39: =E39-F39 -> 39.648182 | K39: =IFERROR(E39/F39-1,"") -> 3.0335258
A40: 6mm Corflute | B40: ='CORFLUTE 6MM ON WEBSITE'!A11 -> 60992 | C40: ='CORFLUTE 6MM ON WEBSITE'!B11 -> Detour Right Arrow 1200x300mm Multi-Message Sign TC231 | D40: ='CORFLUTE 6MM ON WEBSITE'!C11 -> 57.99 | E40: =D40/1.1 -> 52.718182 | F40: ='CORFLUTE 6MM ON WEBSITE'!D11 -> 13.07 | G40: =F40*1.1 -> 14.377 | J40: =E40-F40 -> 39.648182 | K40: =IFERROR(E40/F40-1,"") -> 3.0335258
A41: 6mm Corflute | B41: ='CORFLUTE 6MM ON WEBSITE'!A12 -> 61021 | C41: ='CORFLUTE 6MM ON WEBSITE'!B12 -> Pedestrians Right Arrow 1200x300mm Multi-Message Sign CT284-T8-2R38 | D41: ='CORFLUTE 6MM ON WEBSITE'!C12 -> 57.99 | E41: =D41/1.1 -> 52.718182 | F41: ='CORFLUTE 6MM ON WEBSITE'!D12 -> 13.07 | G41: =F41*1.1 -> 14.377 | J41: =E41-F41 -> 39.648182 | K41: =IFERROR(E41/F41-1,"") -> 3.0335258
A42: 6mm Corflute | B42: ='CORFLUTE 6MM ON WEBSITE'!A13 -> 61022 | C42: ='CORFLUTE 6MM ON WEBSITE'!B13 -> Pedestrians Left Arrow 1200x300mm Multi-Message Sign CT284-T8-2L38 | D42: ='CORFLUTE 6MM ON WEBSITE'!C13 -> 57.99 | E42: =D42/1.1 -> 52.718182 | F42: ='CORFLUTE 6MM ON WEBSITE'!D13 -> 13.07 | G42: =F42*1.1 -> 14.377 | J42: =E42-F42 -> 39.648182 | K42: =IFERROR(E42/F42-1,"") -> 3.0335258
A43: Poly | B43: ='POLY ON WEBSITE'!A1 -> 1046218 | C43: ='POLY ON WEBSITE'!B1 -> Security Notice This Area Is Under 24 Hours W'Picto Poly 450x300 SW023LSP | D43: ='POLY ON WEBSITE'!C1 -> 37.99 | E43: =D43/1.1 -> 34.536364 | F43: ='POLY ON WEBSITE'!D1 -> 5.35 | G43: =F43*1.1 -> 5.885 | J43: =E43-F43 -> 29.186364 | K43: =IFERROR(E43/F43-1,"") -> 5.4553951 | L43: =IF('POLY ON WEBSITE'!F1="","",'POLY ON WEBSITE'!F1) -> QOUTED ALL ON NON REFLECTIVE 2105, NO INFO ONLINE REGARDING REFLECTIVITY.
A44: Poly | B44: ='POLY ON WEBSITE'!A2 -> 685029 | C44: ='POLY ON WEBSITE'!B2 -> 103MP 14M-LP Sign Eye Protection Must Be Worn Poly 300x225 | D44: ='POLY ON WEBSITE'!C2 -> 24.99 | E44: =D44/1.1 -> 22.718182 | F44: ='POLY ON WEBSITE'!D2 -> 2.67 | G44: =F44*1.1 -> 2.937 | J44: =E44-F44 -> 20.048182 | K44: =IFERROR(E44/F44-1,"") -> 7.5086823 | L44: =IF('POLY ON WEBSITE'!F2="","",'POLY ON WEBSITE'!F2)
A45: Poly | B45: ='POLY ON WEBSITE'!A3 -> 685151 | C45: ='POLY ON WEBSITE'!B3 -> Building Site Sign All Visitors Must Report To Site Office Poly 600x450 116LP | D45: ='POLY ON WEBSITE'!C3 -> 44.99 | E45: =D45/1.1 -> 40.9 | F45: ='POLY ON WEBSITE'!D3 -> 10.69 | G45: =F45*1.1 -> 11.759 | J45: =E45-F45 -> 30.21 | K45: =IFERROR(E45/F45-1,"") -> 2.8260056 | L45: =IF('POLY ON WEBSITE'!F3="","",'POLY ON WEBSITE'!F3)
A46: Poly | B46: ='POLY ON WEBSITE'!A4 -> 685177 | C46: ='POLY ON WEBSITE'!B4 -> 204MP 55D-LP Sign Danger No Smoking No Naked Flame Poly 300x225 | D46: ='POLY ON WEBSITE'!C4 -> 24.99 | E46: =D46/1.1 -> 22.718182 | F46: ='POLY ON WEBSITE'!D4 -> 2.67 | G46: =F46*1.1 -> 2.937 | J46: =E46-F46 -> 20.048182 | K46: =IFERROR(E46/F46-1,"") -> 7.5086823 | L46: =IF('POLY ON WEBSITE'!F4="","",'POLY ON WEBSITE'!F4)
A47: Poly | B47: ='POLY ON WEBSITE'!A5 -> 685231 | C47: ='POLY ON WEBSITE'!B5 -> 217LP 127D-NP Sign Danger Construction Site Do Not Enter Poly 600x400 | D47: ='POLY ON WEBSITE'!C5 -> 44.99 | E47: =D47/1.1 -> 40.9 | F47: ='POLY ON WEBSITE'!D5 -> 9.5 | G47: =F47*1.1 -> 10.45 | J47: =E47-F47 -> 31.4 | K47: =IFERROR(E47/F47-1,"") -> 3.3052632 | L47: =IF('POLY ON WEBSITE'!F5="","",'POLY ON WEBSITE'!F5)
A48: Poly | B48: ='POLY ON WEBSITE'!A6 -> 685255 | C48: ='POLY ON WEBSITE'!B6 -> Danger Sign Demolition Work In Progress Poly 600x450 223LP | D48: ='POLY ON WEBSITE'!C6 -> 44.99 | E48: =D48/1.1 -> 40.9 | F48: ='POLY ON WEBSITE'!D6 -> 10.69 | G48: =F48*1.1 -> 11.759 | J48: =E48-F48 -> 30.21 | K48: =IFERROR(E48/F48-1,"") -> 2.8260056 | L48: =IF('POLY ON WEBSITE'!F6="","",'POLY ON WEBSITE'!F6)
A49: Poly | B49: ='POLY ON WEBSITE'!A7 -> 685265 | C49: ='POLY ON WEBSITE'!B7 -> 225LSP 96D-MP Sign Danger Confined Space Entry By Permit Poly 450x300 | D49: ='POLY ON WEBSITE'!C7 -> 32.99 | E49: =D49/1.1 -> 29.990909 | F49: ='POLY ON WEBSITE'!D7 -> 5.35 | G49: =F49*1.1 -> 5.885 | J49: =E49-F49 -> 24.640909 | K49: =IFERROR(E49/F49-1,"") -> 4.6057774 | L49: =IF('POLY ON WEBSITE'!F7="","",'POLY ON WEBSITE'!F7)
A50: Poly | B50: ='POLY ON WEBSITE'!A8 -> 685612 | C50: ='POLY ON WEBSITE'!B8 -> 501LSP 20E-MP 835331 Sign First Aid Poly 450x300 | D50: ='POLY ON WEBSITE'!C8 -> 49.99 | E50: =D50/1.1 -> 45.445455 | F50: ='POLY ON WEBSITE'!D8 -> 5.35 | G50: =F50*1.1 -> 5.885 | J50: =E50-F50 -> 40.095455 | K50: =IFERROR(E50/F50-1,"") -> 7.4944775 | L50: =IF('POLY ON WEBSITE'!F8="","",'POLY ON WEBSITE'!F8)
A51: Poly | B51: ='POLY ON WEBSITE'!A9 -> 685622 | C51: ='POLY ON WEBSITE'!B9 -> 502MP 75E-LP Sign First Aid Station Poly 300x225 | D51: ='POLY ON WEBSITE'!C9 -> 27.99 | E51: =D51/1.1 -> 25.445455 | F51: ='POLY ON WEBSITE'!D9 -> 2.67 | G51: =F51*1.1 -> 2.937 | J51: =E51-F51 -> 22.775455 | K51: =IFERROR(E51/F51-1,"") -> 8.5301328 | L51: =IF('POLY ON WEBSITE'!F9="","",'POLY ON WEBSITE'!F9)
A52: Poly | B52: ='POLY ON WEBSITE'!A10 -> 685659 | C52: ='POLY ON WEBSITE'!B10 -> 509LP 88E-NP Sign Emergency Assembly AREA Poly 600x400 | D52: ='POLY ON WEBSITE'!C10 -> 44.99 | E52: =D52/1.1 -> 40.9 | F52: ='POLY ON WEBSITE'!D10 -> 9.5 | G52: =F52*1.1 -> 10.45 | J52: =E52-F52 -> 31.4 | K52: =IFERROR(E52/F52-1,"") -> 3.3052632 | L52: =IF('POLY ON WEBSITE'!F10="","",'POLY ON WEBSITE'!F10)
...

Sheet Market Comparison
A1: Market-Wide Price Comparison — Our Pricing, RSEA & 9 Retailers (All GST Bases Confirmed)
A2: Methodology: all 9 retailers' GST treatment is now confirmed (4 stated it directly on-site; the remaining 5 — Safety Signs Australia, SafetyXpress, Traffic Control Products, National Safety Signs, Seton — were confirmed by direct check). Safety Signs Australia, SafetyXpress, National Safety Signs and Seton display prices INC GST; Traffic Control Products displays EX GST; HiVis displays EX GST; Jaybro and eSafety Supplies display both inc and ex GST directly; All Trades Group marks its prices "Tax included" (INC GST). Every price below is shown both ex and inc GST, with whichever figure is NOT the retailer's own displayed figure calculated (×1.1 or ÷1.1). Our Quoted Price (both 1200- and 1220-stock) and the RSEA Website Price are pulled by formula from the 'RSEA vs Quoted Comparison' tab; competitor figures were captured live from each retailer's own website on 14 October 2026 and are hardcoded (not formulas) since they come from outside this workbook.
A3: Where a retailer did not carry the exact size/material of our line item, the closest equivalent sign TYPE was used instead and the mismatch is flagged in the Notes column — treat those rows as directionally indicative, not an exact apples-to-apples match. "N/A" means that retailer does not appear to carry a comparable product (confirmed via the research, not a blank/forgotten cell). Seton additionally blocked direct automated access (403/bot protection) during research, so its prices were recovered from search-engine cache only and are flagged LOW CONFIDENCE in the Notes column — that is a data-reliability flag, separate from its (confirmed) GST treatment. Sources: hivis.com/collections/signage · jaybro.com.au/road-traffic/permanent-signs/regulatory-signs/ · alltradesgroup.net.au/collections/site-safety-signage-roads-traffic-signs · esafetysupplies.com.au/collections/traffic-road-safety-sign · safetysigns.com.au/collections/road-car-park-signs · safetyxpress.com.au/traffic-signs/ · trafficcontrolproducts.com.au/collections/road-signs-traffic · nationalsafetysigns.com.au/product-category/road-and-traffic-signs/road-signs/ · seton.net.au. Captured 14 October 2026.
A5: Category | B5: RSEA Code | C5: Product / Sign | D5: Our Quoted Price (ex GST) | E5: Our Quoted Price (inc GST) | F5: Our Quoted Price - 1220 Stock (ex GST) | G5: Our Quoted Price - 1220 Stock (inc GST) | H5: RSEA Website Price (inc GST) | I5: RSEA Website Price (ex GST) | J5: HiVis (ex GST, as shown) | K5: HiVis (inc GST, calc.) | L5: Jaybro (inc GST, as shown) | M5: Jaybro (ex GST, as shown) | N5: All Trades Group (inc GST, as shown) | O5: All Trades Group (ex GST, calc.) | P5: eSafety Supplies (inc GST, as shown) | Q5: eSafety Supplies (ex GST, as shown) | R5: Safety Signs Australia (inc GST, as shown) | S5: Safety Signs Australia (ex GST, calc.) | T5: SafetyXpress (inc GST, as shown) | U5: SafetyXpress (ex GST, calc.) | V5: Traffic Control Products (ex GST, as shown) | W5: Traffic Control Products (inc GST, calc.) | X5: National Safety Signs (inc GST, as shown) | Y5: National Safety Signs (ex GST, calc.) | Z5: Seton (inc GST, as shown) | AA5: Seton (ex GST, calc.) | AB5: Cheapest of RSEA + 9 Competitors (ex GST) | AC5: Our Quote (1200 Stock) vs Cheapest (ex GST; neg. = we're cheaper) | AD5: Our Quote (1220 Stock) vs Cheapest (ex GST; neg. = we're cheaper) | AE5: Notes / Match Basis
A6: 1.6mm Aluminium | B6: 114090 | C6: Security Sign This Area Is Under 24 Hour Surv Metal 450x300 SW023LSM | D6: ='RSEA vs Quoted Comparison'!F6 -> 16.71 | E6: ='RSEA vs Quoted Comparison'!G6 -> 18.381 | F6: =IF('RSEA vs Quoted Comparison'!H6="","",'RSEA vs Quoted Comparison'!H6) -> 16.93275 | G6: =IF('RSEA vs Quoted Comparison'!I6="","",'RSEA vs Quoted Comparison'!I6) -> 18.626025 | H6: ='RSEA vs Quoted Comparison'!D6 -> 42.99 | I6: ='RSEA vs Quoted Comparison'!E6 -> 39.081818 | J6: N/A | K6: N/A | L6: N/A | M6: N/A | N6: 42.5 | O6: =N6/1.1 -> 38.636364 | P6: 22.05 | Q6: 20.05 | R6: 30 | S6: =R6/1.1 -> 27.272727 | T6: 31.19 | U6: =T6/1.1 -> 28.354545 | V6: N/A | W6: N/A | X6: 10.29 | Y6: =X6/1.1 -> 9.3545455 | Z6: 65.63 | AA6: =Z6/1.1 -> 59.663636 | AB6: =IF(COUNT(I6,K6,M6,O6,Q6,S6,U6,W6,Y6,AA6)=0,"N/A",MIN(I6,K6,M6,O6,Q6,S6,U6,W6,Y6,AA6)) -> 9.3545455 | AC6: =IF(OR(D6="",AB6="",AB6="N/A"),"N/A",D6/AB6-1) -> 0.78629738 | AD6: =IF(OR(F6="",AB6="",AB6="N/A"),"N/A",F6/AB6-1) -> 0.81010933 | AE6: All Trades Group: 300x225 poly or 600x450; no exact 450x300 | eSafety Supplies: 600x450 also stocked | Safety Signs Australia: 450x600, size differs | SafetyXpress: 3 sizes incl 300x450 | National Safety Signs: From, S2870 | Seton: LOW conf; 'Video Surveillance In Use', 300-450mm range
A7: 1.6mm Aluminium | B7: 201032 | C7: Uniform Safety Flat Plate Swing Stand Reduce Speed Metal SG519-ALUM | D7: ='RSEA vs Quoted Comparison'!F7 -> 66.83 | E7: ='RSEA vs Quoted Comparison'!G7 -> 73.513 | F7: =IF('RSEA vs Quoted Comparison'!H7="","",'RSEA vs Quoted Comparison'!H7) | G7: =IF('RSEA vs Quoted Comparison'!I7="","",'RSEA vs Quoted Comparison'!I7) | H7: ='RSEA vs Quoted Comparison'!D7 -> 134.99 | I7: ='RSEA vs Quoted Comparison'!E7 -> 122.71818 | J7: N/A | K7: N/A | L7: N/A | M7: N/A | N7: N/A | O7: N/A | P7: N/A | Q7: N/A | R7: N/A | S7: N/A | T7: N/A | U7: N/A | V7: N/A | W7: N/A | X7: N/A | Y7: N/A | AB7: =IF(COUNT(I7,K7,M7,O7,Q7,S7,U7,W7,Y7,AA7)=0,"N/A",MIN(I7,K7,M7,O7,Q7,S7,U7,W7,Y7,AA7)) -> 122.71818 | AC7: =IF(OR(D7="",AB7="",AB7="N/A"),"N/A",D7/AB7-1) -> -0.45541892 | AD7: =IF(OR(F7="",AB7="",AB7="N/A"),"N/A",F7/AB7-1) -> N/A | AE7: Swing-stand temporary traffic-control sign - no comparable product found at any of the 9 researched retailers.
A8: 1.6mm Aluminium | B8: 201033 | C8: Unifrom Safety Sign Flate Plat Swing Stand End Roadwork Metal SG501-ALUM | D8: ='RSEA vs Quoted Comparison'!F8 -> 44.55 | E8: ='RSEA vs Quoted Comparison'!G8 -> 49.005 | F8: =IF('RSEA vs Quoted Comparison'!H8="","",'RSEA vs Quoted Comparison'!H8) | G8: =IF('RSEA vs Quoted Comparison'!I8="","",'RSEA vs Quoted Comparison'!I8) | H8: ='RSEA vs Quoted Comparison'!D8 -> 167.99 | I8: ='RSEA vs Quoted Comparison'!E8 -> 152.71818 | J8: N/A | K8: N/A | L8: N/A | M8: N/A | N8: N/A | O8: N/A | P8: N/A | Q8: N/A | R8: N/A | S8: N/A | T8: N/A | U8: N/A | V8: N/A | W8: N/A | X8: N/A | Y8: N/A | AB8: =IF(COUNT(I8,K8,M8,O8,Q8,S8,U8,W8,Y8,AA8)=0,"N/A",MIN(I8,K8,M8,O8,Q8,S8,U8,W8,Y8,AA8)) -> 152.71818 | AC8: =IF(OR(D8="",AB8="",AB8="N/A"),"N/A",D8/AB8-1) -> -0.70828621 | AD8: =IF(OR(F8="",AB8="",AB8="N/A"),"N/A",F8/AB8-1) -> N/A | AE8: Swing-stand temporary traffic-control sign - no comparable product found at any of the 9 researched retailers.
A9: 1.6mm Aluminium | B9: 60268 | C9: Stop 600mm Octagonal Metal Traffic Sign R1-1A-1X | D9: ='RSEA vs Quoted Comparison'!F9 -> 44.55 | E9: ='RSEA vs Quoted Comparison'!G9 -> 49.005 | F9: =IF('RSEA vs Quoted Comparison'!H9="","",'RSEA vs Quoted Comparison'!H9) -> 45.144 | G9: =IF('RSEA vs Quoted Comparison'!I9="","",'RSEA vs Quoted Comparison'!I9) -> 49.6584 | H9: ='RSEA vs Quoted Comparison'!D9 -> 147.99 | I9: ='RSEA vs Quoted Comparison'!E9 -> 134.53636 | J9: =K9*1.1 -> 71.038 | K9: 64.58 | L9: 93.25 | M9: 84.77 | N9: 99 | O9: =N9/1.1 -> 90 | P9: 77.4 | Q9: 70.36 | R9: 92.4 | S9: =R9/1.1 -> 84 | T9: 106.09 | U9: =T9/1.1 -> 96.445455 | V9: =W9*1.1 -> 69.245 | W9: 62.95 | X9: 117.4 | Y9: =X9/1.1 -> 106.72727 | Z9: 128.81 | AA9: =Z9/1.1 -> 117.1 | AB9: =IF(COUNT(I9,K9,M9,O9,Q9,S9,U9,W9,Y9,AA9)=0,"N/A",MIN(I9,K9,M9,O9,Q9,S9,U9,W9,Y9,AA9)) -> 62.95 | AC9: =IF(OR(D9="",AB9="",AB9="N/A"),"N/A",D9/AB9-1) -> -0.29229547 | AD9: =IF(OR(F9="",AB9="",AB9="N/A"),"N/A",F9/AB9-1) -> -0.28285941 | AE9: HiVis: 600x600/750x750/900x900 options | Jaybro: 600x600 exact | All Trades Group: 600mm (450/600/750 avail) | eSafety Supplies: 600x600 exact | Safety Signs Australia: 600x600 Class1 refl alu | SafetyXpress: range 84.67-127.50, midpoint used | Traffic Control Products: 600x600 'Hexagonal' CL1X (alt 750x750=$75) | National Safety Signs: From, 600x600 or 750x750 | Seton: LOW conf - conflicting cache (also 183.95/169.50)
A10: 1.6mm Aluminium | B10: 60273 | C10: Give Way 750mm Triangle Metal Traffic Sign R1-2A | D10: ='RSEA vs Quoted Comparison'!F10 -> 69.61 | E10: ='RSEA vs Quoted Comparison'!G10 -> 76.571 | F10: =IF('RSEA vs Quoted Comparison'!H10="","",'RSEA vs Quoted Comparison'!H10) -> 70.538125 | G10: =IF('RSEA vs Quoted Comparison'!I10="","",'RSEA vs Quoted Comparison'!I10) -> 77.591938 | H10: ='RSEA vs Quoted Comparison'!D10 -> 167.99 | I10: ='RSEA vs Quoted Comparison'!E10 -> 152.71818 | J10: =K10*1.1 -> 84.15 | K10: 76.5 | L10: 117.3 | M10: 106.64 | N10: 124.95 | O10: =N10/1.1 -> 113.59091 | P10: 95.4 | Q10: 86.73 | R10: 118.8 | S10: =R10/1.1 -> 108 | T10: 98.18 | U10: =T10/1.1 -> 89.254545 | V10: =W10*1.1 -> 81.4 | W10: 74 | X10: 128.32 | Y10: =X10/1.1 -> 116.65455 | Z10: 220.92 | AA10: =Z10/1.1 -> 200.83636 | AB10: =IF(COUNT(I10,K10,M10,O10,Q10,S10,U10,W10,Y10,AA10)=0,"N/A",MIN(I10,K10,M10,O10,Q10,S10,U10,W10,Y10,AA10)) -> 74 | AC10: =IF(OR(D10="",AB10="",AB10="N/A"),"N/A",D10/AB10-1) -> -0.059324324 | AD10: =IF(OR(F10="",AB10="",AB10="N/A"),"N/A",F10/AB10-1) -> -0.046782095 | AE10: HiVis: 750/900/1200mm | Jaybro: 750x750 exact | All Trades Group: 750mm triangular | eSafety Supplies: 750mm triangle | Safety Signs Australia: 750mm | SafetyXpress: 750mm | Traffic Control Products: 750mm | National Safety Signs: From, 750 or 900mm | Seton: LOW conf - 6-pack bulk tier price, single-unit unconfirmed
A11: 1.6mm Aluminium | B11: 60290 | C11: Keep Left Arrow 450x600mm Metal Traffic Sign R2-3AL | D11: ='RSEA vs Quoted Comparison'!F11 -> 33.41 | E11: ='RSEA vs Quoted Comparison'!G11 -> 36.751 | F11: =IF('RSEA vs Quoted Comparison'!H11="","",'RSEA vs Quoted Comparison'!H11) -> 33.8555 | G11: =IF('RSEA vs Quoted Comparison'!I11="","",'RSEA vs Quoted Comparison'!I11) -> 37.24105 | H11: ='RSEA vs Quoted Comparison'!D11 -> 142.99 | I11: ='RSEA vs Quoted Comparison'!E11 -> 129.99091 | J11: =K11*1.1 -> 44.209 | K11: 40.19 | L11: 63.11 | M11: 57.37 | N11: 90.3 | O11: =N11/1.1 -> 82.090909 | P11: 57 | Q11: 51.82 | R11: 74.8 | S11: =R11/1.1 -> 68 | T11: 78.64 | U11: =T11/1.1 -> 71.490909 | V11: =W11*1.1 -> 63.8 | W11: 58 | X11: 80.22 | Y11: =X11/1.1 -> 72.927273 | Z11: 173.98 | AA11: =Z11/1.1 -> 158.16364 | AB11: =IF(COUNT(I11,K11,M11,O11,Q11,S11,U11,W11,Y11,AA11)=0,"N/A",MIN(I11,K11,M11,O11,Q11,S11,U11,W11,Y11,AA11)) -> 40.19 | AC11: =IF(OR(D11="",AB11="",AB11="N/A"),"N/A",D11/AB11-1) -> -0.16869868 | AD11: =IF(OR(F11="",AB11="",AB11="N/A"),"N/A",F11/AB11-1) -> -0.15761383 | AE11: HiVis: 300x400/450x600/600x800 | Jaybro: 450x600 exact | All Trades Group: 600x450mm | eSafety Supplies: 450x600 exact, sale price (was 86.65) | Safety Signs Australia: 450x600 | SafetyXpress: 450x600 | Traffic Control Products: 450x600 | National Safety Signs: From, 400x300/600x450/800x600 | Seton: MEDIUM conf, 450x600
A12: 1.6mm Aluminium | B12: 60314 | C12: Lime Green Pedestrian Crossing Sign 600mm | D12: ='RSEA vs Quoted Comparison'!F12 -> 44.55 | E12: ='RSEA vs Quoted Comparison'!G12 -> 49.005 | F12: =IF('RSEA vs Quoted Comparison'!H12="","",'RSEA vs Quoted Comparison'!H12) -> 45.144 | G12: =IF('RSEA vs Quoted Comparison'!I12="","",'RSEA vs Quoted Comparison'!I12) -> 49.6584 | H12: ='RSEA vs Quoted Comparison'!D12 -> 157.99 | I12: ='RSEA vs Quoted Comparison'!E12 -> 143.62727 | J12: =K12*1.1 -> 88.781 | K12: 80.71 | L12: 95.35 | M12: 86.68 | N12: 105.6 | O12: =N12/1.1 -> 96 | P12: 77.4 | Q12: 70.36 | R12: 107.8 | S12: =R12/1.1 -> 98 | T12: 94.5 | U12: =T12/1.1 -> 85.909091 | V12: =W12*1.1 -> 97.35 | W12: 88.5 | X12: 127.75 | Y12: =X12/1.1 -> 116.13636 | Z12: 179.74 | AA12: =Z12/1.1 -> 163.4 | AB12: =IF(COUNT(I12,K12,M12,O12,Q12,S12,U12,W12,Y12,AA12)=0,"N/A",MIN(I12,K12,M12,O12,Q12,S12,U12,W12,Y12,AA12)) -> 70.36 | AC12: =IF(OR(D12="",AB12="",AB12="N/A"),"N/A",D12/AB12-1) -> -0.36682774 | AD12: =IF(OR(F12="",AB12="",AB12="N/A"),"N/A",F12/AB12-1) -> -0.35838545 | AE12: HiVis: 600/750/900mm | Jaybro: 600mm exact | All Trades Group: 600x600 or 750x750 (W6-1, size differs from 600mm round) | eSafety Supplies: 600mm exact | Safety Signs Australia: 600mm dia | SafetyXpress: 600mm dia | Traffic Control Products: 600mm dia | National Safety Signs: From, 600 or 750mm round | Seton: MEDIUM conf, 600mm dia
A13: 1.6mm Aluminium | B13: 61041 | C13: Regulatory Sign Speed Restriction 10km 450x600mm Metal | D13: ='RSEA vs Quoted Comparison'!F13 -> 33.41 | E13: ='RSEA vs Quoted Comparison'!G13 -> 36.751 | F13: =IF('RSEA vs Quoted Comparison'!H13="","",'RSEA vs Quoted Comparison'!H13) -> 33.8555 | G13: =IF('RSEA vs Quoted Comparison'!I13="","",'RSEA vs Quoted Comparison'!I13) -> 37.24105 | H13: ='RSEA vs Quoted Comparison'!D13 -> 142.99 | I13: ='RSEA vs Quoted Comparison'!E13 -> 129.99091 | J13: =K13*1.1 -> 109.153 | K13: 99.23 | L13: 61.59 | M13: 55.99 | N13: 36.5 | O13: =N13/1.1 -> 33.181818 | P13: 57 | Q13: 51.82 | R13: 74.8 | S13: =R13/1.1 -> 68 | T13: 31.19 | U13: =T13/1.1 -> 28.354545 | V13: N/A | W13: N/A | X13: 110.1 | Y13: =X13/1.1 -> 100.09091 | Z13: 44 | AA13: =Z13/1.1 -> 40 | AB13: =IF(COUNT(I13,K13,M13,O13,Q13,S13,U13,W13,Y13,AA13)=0,"N/A",MIN(I13,K13,M13,O13,Q13,S13,U13,W13,Y13,AA13)) -> 28.354545 | AC13: =IF(OR(D13="",AB13="",AB13="N/A"),"N/A",D13/AB13-1) -> 0.17829433 | AD13: =IF(OR(F13="",AB13="",AB13="N/A"),"N/A",F13/AB13-1) -> 0.19400609 | AE13: HiVis: 10km/h, 450x600/600x800/900x1200 | Jaybro: 10km/h, 450x600 exact | All Trades Group: 10km/h, 300x225 or 600x450 | eSafety Supplies: 10km/h, 450x600 exact | Safety Signs Australia: 10km/h, 450x600 | SafetyXpress: 10km/h, upper of 25.64-31.19 range, 450x600 | Traffic Control Products: Not stocked - site only has 40-100km/h plates | National Safety Signs: From; custom-text R4-1 sign, speed typed in, shared across all speed rows | Seton: LOW conf, ~42-46 range, 450x600 Flute not alu
A14: 1.6mm Aluminium | B14: 61138 | C14: Regulatory Sign No Entry Metal 450x450 R2-4A-1 | D14: ='RSEA vs Quoted Comparison'!F14 -> 25.06 | E14: ='RSEA vs Quoted Comparison'!G14 -> 27.566 | F14: =IF('RSEA vs Quoted Comparison'!H14="","",'RSEA vs Quoted Comparison'!H14) -> 25.394125 | G14: =IF('RSEA vs Quoted Comparison'!I14="","",'RSEA vs Quoted Comparison'!I14) -> 27.933537 | H14: ='RSEA vs Quoted Comparison'!D14 -> 112.99 | I14: ='RSEA vs Quoted Comparison'!E14 -> 102.71818 | J14: =K14*1.1 -> 77.968 | K14: 70.88 | L14: 61.29 | M14: 55.72 | N14: 49.5 | O14: =N14/1.1 -> 45 | P14: 47.4 | Q14: 43.09 | R14: 61.6 | S14: =R14/1.1 -> 56 | T14: 76.56 | U14: =T14/1.1 -> 69.6 | V14: =W14*1.1 -> 69.245 | W14: 62.95 | X14: 100.71 | Y14: =X14/1.1 -> 91.554545 | Z14: 159.24 | AA14: =Z14/1.1 -> 144.76364 | AB14: =IF(COUNT(I14,K14,M14,O14,Q14,S14,U14,W14,Y14,AA14)=0,"N/A",MIN(I14,K14,M14,O14,Q14,S14,U14,W14,Y14,AA14)) -> 43.09 | AC14: =IF(OR(D14="",AB14="",AB14="N/A"),"N/A",D14/AB14-1) -> -0.41842655 | AD14: =IF(OR(F14="",AB14="",AB14="N/A"),"N/A",F14/AB14-1) -> -0.41067243 | AE14: HiVis: 450x750, size differs from 450x450 | Jaybro: 450x450 exact | All Trades Group: 600x450, size differs | eSafety Supplies: 450x450 exact | Safety Signs Australia: 450x450 exact | SafetyXpress: range 72.28-80.84, 450x450 exact | Traffic Control Products: 450x750, size differs | National Safety Signs: From, 450x450 avail | Seton: MEDIUM conf, 750x750 (not 450x450)
A15: 1.6mm Aluminium | B15: 685224 | C15: 216MM 25D-LM Sign Danger Forklift Operating Area Metal 300x225 | D15: ='RSEA vs Quoted Comparison'!F15 -> 8.35 | E15: ='RSEA vs Quoted Comparison'!G15 -> 9.185 | F15: =IF('RSEA vs Quoted Comparison'!H15="","",'RSEA vs Quoted Comparison'!H15) -> 8.461375 | G15: =IF('RSEA vs Quoted Comparison'!I15="","",'RSEA vs Quoted Comparison'!I15) -> 9.3075125 | H15: ='RSEA vs Quoted Comparison'!D15 -> 32.99 | I15: ='RSEA vs Quoted Comparison'!E15 -> 29.990909 | J15: N/A | K15: N/A | L15: N/A | M15: N/A | N15: N/A | O15: N/A | P15: N/A | Q15: N/A | R15: N/A | S15: N/A | T15: N/A | U15: N/A | V15: N/A | W15: N/A | X15: N/A | Y15: N/A | AB15: =IF(COUNT(I15,K15,M15,O15,Q15,S15,U15,W15,Y15,AA15)=0,"N/A",MIN(I15,K15,M15,O15,Q15,S15,U15,W15,Y15,AA15)) -> 29.990909 | AC15: =IF(OR(D15="",AB15="",AB15="N/A"),"N/A",D15/AB15-1) -> -0.7215823 | AD15: =IF(OR(F15="",AB15="",AB15="N/A"),"N/A",F15/AB15-1) -> -0.71786867 | AE15: Generic site/warehouse danger sign - no comparable product found at any of the 9 researched retailers (out of scope: these retailers focus on road/traffic signage).
A16: 1.6mm Aluminium | B16: 685264 | C16: Danger Confined Space Entry By Permit Metal Sign 450x300mm | D16: ='RSEA vs Quoted Comparison'!F16 -> 15.59 | E16: ='RSEA vs Quoted Comparison'!G16 -> 17.149 | F16: =IF('RSEA vs Quoted Comparison'!H16="","",'RSEA vs Quoted Comparison'!H16) -> 15.81275 | G16: =IF('RSEA vs Quoted Comparison'!I16="","",'RSEA vs Quoted Comparison'!I16) -> 17.394025 | H16: ='RSEA vs Quoted Comparison'!D16 -> 44.99 | I16: ='RSEA vs Quoted Comparison'!E16 -> 40.9 | J16: N/A | K16: N/A | L16: N/A | M16: N/A | N16: N/A | O16: N/A | P16: N/A | Q16: N/A | R16: N/A | S16: N/A | T16: N/A | U16: N/A | V16: N/A | W16: N/A | X16: N/A | Y16: N/A | AB16: =IF(COUNT(I16,K16,M16,O16,Q16,S16,U16,W16,Y16,AA16)=0,"N/A",MIN(I16,K16,M16,O16,Q16,S16,U16,W16,Y16,AA16)) -> 40.9 | AC16: =IF(OR(D16="",AB16="",AB16="N/A"),"N/A",D16/AB16-1) -> -0.61882641 | AD16: =IF(OR(F16="",AB16="",AB16="N/A"),"N/A",F16/AB16-1) -> -0.6133802 | AE16: No metal-sign equivalent found at the 9 researched retailers for this specific size/material. See RSEA 685265 (Poly, Confined Space Entry By Permit) below for comparable market data.
A17: 1.6mm Aluminium | B17: 685642 | C17: First Aid Emergency Eye Wash Metal Sign 300x225mm 506MM | D17: ='RSEA vs Quoted Comparison'!F17 -> 8.35 | E17: ='RSEA vs Quoted Comparison'!G17 -> 9.185 | F17: =IF('RSEA vs Quoted Comparison'!H17="","",'RSEA vs Quoted Comparison'!H17) -> 8.461375 | G17: =IF('RSEA vs Quoted Comparison'!I17="","",'RSEA vs Quoted Comparison'!I17) -> 9.3075125 | H17: ='RSEA vs Quoted Comparison'!D17 -> 32.99 | I17: ='RSEA vs Quoted Comparison'!E17 -> 29.990909 | J17: N/A | K17: N/A | L17: N/A | M17: N/A | N17: N/A | O17: N/A | P17: N/A | Q17: N/A | R17: N/A | S17: N/A | T17: N/A | U17: N/A | V17: N/A | W17: N/A | X17: N/A | Y17: N/A | AB17: =IF(COUNT(I17,K17,M17,O17,Q17,S17,U17,W17,Y17,AA17)=0,"N/A",MIN(I17,K17,M17,O17,Q17,S17,U17,W17,Y17,AA17)) -> 29.990909 | AC17: =IF(OR(D17="",AB17="",AB17="N/A"),"N/A",D17/AB17-1) -> -0.7215823 | AD17: =IF(OR(F17="",AB17="",AB17="N/A"),"N/A",F17/AB17-1) -> -0.71786867 | AE17: Generic site/warehouse safety sign - no comparable product found at any of the 9 researched retailers.
A18: 1.6mm Aluminium | B18: 685976 | C18: Speed 5km 600x400mm Metal Traffic Sign TC409LM | D18: ='RSEA vs Quoted Comparison'!F18 -> 29.7 | E18: ='RSEA vs Quoted Comparison'!G18 -> 32.67 | F18: =IF('RSEA vs Quoted Comparison'!H18="","",'RSEA vs Quoted Comparison'!H18) -> 30.1455 | G18: =IF('RSEA vs Quoted Comparison'!I18="","",'RSEA vs Quoted Comparison'!I18) -> 33.16005 | H18: ='RSEA vs Quoted Comparison'!D18 -> 69.99 | I18: ='RSEA vs Quoted Comparison'!E18 -> 63.627273 | J18: N/A | K18: N/A | L18: N/A | M18: N/A | N18: N/A | O18: N/A | P18: 57 | Q18: 51.82 | R18: 74.8 | S18: =R18/1.1 -> 68 | T18: 41.13 | U18: =T18/1.1 -> 37.390909 | V18: N/A | W18: N/A | X18: 110.1 | Y18: =X18/1.1 -> 100.09091 | AB18: =IF(COUNT(I18,K18,M18,O18,Q18,S18,U18,W18,Y18,AA18)=0,"N/A",MIN(I18,K18,M18,O18,Q18,S18,U18,W18,Y18,AA18)) -> 37.390909 | AC18: =IF(OR(D18="",AB18="",AB18="N/A"),"N/A",D18/AB18-1) -> -0.20568928 | AD18: =IF(OR(F18="",AB18="",AB18="N/A"),"N/A",F18/AB18-1) -> -0.19377462 | AE18: eSafety Supplies: 5km/h, 450x600 (combined with item 16), not 600x400 | Safety Signs Australia: 5km/h, 450x600, not 600x400 | SafetyXpress: 5km/h plain metal, 450x600 | Traffic Control Products: Not stocked | National Safety Signs: From; shared custom-text speed sign | Seton: Not confirmed
A19: 1.6mm Aluminium | B19: 685980 | C19: Speed 10km 600x400mm Metal Traffic Sign TC410LM | D19: ='RSEA vs Quoted Comparison'!F19 -> 29.7 | E19: ='RSEA vs Quoted Comparison'!G19 -> 32.67 | F19: =IF('RSEA vs Quoted Comparison'!H19="","",'RSEA vs Quoted Comparison'!H19) -> 30.1455 | G19: =IF('RSEA vs Quoted Comparison'!I19="","",'RSEA vs Quoted Comparison'!I19) -> 33.16005 | H19: ='RSEA vs Quoted Comparison'!D19 -> 84.99 | I19: ='RSEA vs Quoted Comparison'!E19 -> 77.263636 | J19: =K19*1.1 -> 109.153 | K19: 99.23 | L19: N/A | M19: N/A | N19: 36.5 | O19: =N19/1.1 -> 33.181818 | P19: 57 | Q19: 51.82 | R19: 74.8 | S19: =R19/1.1 -> 68 | T19: 31.19 | U19: =T19/1.1 -> 28.354545 | V19: N/A | W19: N/A | X19: 110.1 | Y19: =X19/1.1 -> 100.09091 | AB19: =IF(COUNT(I19,K19,M19,O19,Q19,S19,U19,W19,Y19,AA19)=0,"N/A",MIN(I19,K19,M19,O19,Q19,S19,U19,W19,Y19,AA19)) -> 28.354545 | AC19: =IF(OR(D19="",AB19="",AB19="N/A"),"N/A",D19/AB19-1) -> 0.047451106 | AD19: =IF(OR(F19="",AB19="",AB19="N/A"),"N/A",F19/AB19-1) -> 0.063162873 | AE19: HiVis: 10km/h SKU reused, size differs (600x800 etc not 600x400) | All Trades Group: 10km/h SKU reused, size differs | eSafety Supplies: 10km/h, 450x600 (combined with item 5), not 600x400 | Safety Signs Australia: 10km/h SKU reused, size differs | SafetyXpress: 10km/h, size differs | Traffic Control Products: Not stocked | National Safety Signs: From; shared custom-text speed sign
A20: 1.6mm Aluminium | B20: 686188 | C20: Disabled Parking 450x300mm Metal Traffic Sign TC420LSM | D20: ='RSEA vs Quoted Comparison'!F20 -> 16.71 | E20: ='RSEA vs Quoted Comparison'!G20 -> 18.381 | F20: =IF('RSEA vs Quoted Comparison'!H20="","",'RSEA vs Quoted Comparison'!H20) -> 16.93275 | G20: =IF('RSEA vs Quoted Comparison'!I20="","",'RSEA vs Quoted Comparison'!I20) -> 18.626025 | H20: ='RSEA vs Quoted Comparison'!D20 -> 44.99 | I20: ='RSEA vs Quoted Comparison'!E20 -> 40.9 | J20: =K20*1.1 -> 26.653 | K20: 24.23 | L20: 29.61 | M20: 26.92 | N20: 35.7 | O20: =N20/1.1 -> 32.454545 | P20: 33 | Q20: 30 | R20: 27.5 | S20: =R20/1.1 -> 25 | T20: 25.64 | U20: =T20/1.1 -> 23.309091 | V20: N/A | W20: N/A | X20: 26.77 | Y20: =X20/1.1 -> 24.336364 | Z20: 49.78 | AA20: =Z20/1.1 -> 45.254545 | AB20: =IF(COUNT(I20,K20,M20,O20,Q20,S20,U20,W20,Y20,AA20)=0,"N/A",MIN(I20,K20,M20,O20,Q20,S20,U20,W20,Y20,AA20)) -> 23.309091 | AC20: =IF(OR(D20="",AB20="",AB20="N/A"),"N/A",D20/AB20-1) -> -0.28311232 | AD20: =IF(OR(F20="",AB20="",AB20="N/A"),"N/A",F20/AB20-1) -> -0.27355597 | AE20: HiVis: 225x450, size differs from 450x300 | Jaybro: 225x450, size differs | All Trades Group: 300x225, size differs | eSafety Supplies: 225x450, closest size | Safety Signs Australia: 300x450, size differs | SafetyXpress: 300x450, size differs | Traffic Control Products: Not found | National Safety Signs: From | Seton: From, inc GST, 300x450
A21: 1.6mm Aluminium | B21: 686503 | C21: Traffic Sign No Parking Metal 600x450 TC426LM | D21: ='RSEA vs Quoted Comparison'!F21 -> 33.41 | E21: ='RSEA vs Quoted Comparison'!G21 -> 36.751 | F21: =IF('RSEA vs Quoted Comparison'!H21="","",'RSEA vs Quoted Comparison'!H21) -> 33.8555 | G21: =IF('RSEA vs Quoted Comparison'!I21="","",'RSEA vs Quoted Comparison'!I21) -> 37.24105 | H21: ='RSEA vs Quoted Comparison'!D21 -> 64.99 | I21: ='RSEA vs Quoted Comparison'!E21 -> 59.081818 | J21: =K21*1.1 -> 26.653 | K21: 24.23 | L21: 31.89 | M21: 28.99 | N21: 53.4 | O21: =N21/1.1 -> 48.545455 | P21: 45 | Q21: 40.91 | R21: N/A | S21: N/A | T21: 82.82 | U21: =T21/1.1 -> 75.290909 | V21: N/A | W21: N/A | X21: 23.32 | Y21: =X21/1.1 -> 21.2 | AB21: =IF(COUNT(I21,K21,M21,O21,Q21,S21,U21,W21,Y21,AA21)=0,"N/A",MIN(I21,K21,M21,O21,Q21,S21,U21,W21,Y21,AA21)) -> 21.2 | AC21: =IF(OR(D21="",AB21="",AB21="N/A"),"N/A",D21/AB21-1) -> 0.5759434 | AD21: =IF(OR(F21="",AB21="",AB21="N/A"),"N/A",F21/AB21-1) -> 0.59695755 | AE21: HiVis: 225x450, much smaller than 600x450 target | Jaybro: 225x450, size differs | All Trades Group: 225x450, size differs | eSafety Supplies: 300x450 shown / 600x450 also stocked | Safety Signs Australia: Not found - only 300x450 exists | SafetyXpress: 600x450 variant, exact size | Traffic Control Products: Only directional-arrow variants stocked | National Safety Signs: From, generic RD124
A22: 1.6mm Aluminium | B22: 686829 | C22: No Standing Anytime Double Arrow Symbolic Metal 300 x 450mm | D22: ='RSEA vs Quoted Comparison'!F22 -> 11.81 | E22: ='RSEA vs Quoted Comparison'!G22 -> 12.991 | F22: =IF('RSEA vs Quoted Comparison'!H22="","",'RSEA vs Quoted Comparison'!H22) -> 12.03275 | G22: =IF('RSEA vs Quoted Comparison'!I22="","",'RSEA vs Quoted Comparison'!I22) -> 13.236025 | H22: ='RSEA vs Quoted Comparison'!D22 -> 44.99 | I22: ='RSEA vs Quoted Comparison'!E22 -> 40.9 | J22: N/A | K22: N/A | L22: 29.61 | M22: 26.92 | N22: 42.5 | O22: =N22/1.1 -> 38.636364 | P22: 24.2 | Q22: 22 | R22: 27.5 | S22: =R22/1.1 -> 25 | T22: 33.12 | U22: =T22/1.1 -> 30.109091 | V22: N/A | W22: N/A | X22: 23.32 | Y22: =X22/1.1 -> 21.2 | Z22: 48.85 | AA22: =Z22/1.1 -> 44.409091 | AB22: =IF(COUNT(I22,K22,M22,O22,Q22,S22,U22,W22,Y22,AA22)=0,"N/A",MIN(I22,K22,M22,O22,Q22,S22,U22,W22,Y22,AA22)) -> 21.2 | AC22: =IF(OR(D22="",AB22="",AB22="N/A"),"N/A",D22/AB22-1) -> -0.44292453 | AD22: =IF(OR(F22="",AB22="",AB22="N/A"),"N/A",F22/AB22-1) -> -0.43241745 | AE22: Jaybro: 225x450, size differs from 300x450 | All Trades Group: 'No Stopping' dual arrow closest wording, 225x450 | eSafety Supplies: 300x450 exact | Safety Signs Australia: 300x450 exact | SafetyXpress: 300x450 exact (upper of range) | Traffic Control Products: Not found | National Safety Signs: From, 'Bi-Directional' closest to double arrow | Seton: LOW conf - promo pricing, 300x450 exact
A23: 1.6mm Aluminium | B23: 712752 | C23: 840307 TC426LSM Sign No Parking Metal 450x300 | D23: ='RSEA vs Quoted Comparison'!F23 -> 11.81 | E23: ='RSEA vs Quoted Comparison'!G23 -> 12.991 | F23: =IF('RSEA vs Quoted Comparison'!H23="","",'RSEA vs Quoted Comparison'!H23) -> 12.03275 | G23: =IF('RSEA vs Quoted Comparison'!I23="","",'RSEA vs Quoted Comparison'!I23) -> 13.236025 | H23: ='RSEA vs Quoted Comparison'!D23 -> 49.99 | I23: ='RSEA vs Quoted Comparison'!E23 -> 45.445455 | J23: =K23*1.1 -> 26.653 | K23: 24.23 | L23: 31.21 | M23: 28.37 | N23: 53.4 | O23: =N23/1.1 -> 48.545455 | P23: 24.2 | Q23: 22 | R23: 27.5 | S23: =R23/1.1 -> 25 | T23: 33.33 | U23: =T23/1.1 -> 30.3 | V23: N/A | W23: N/A | X23: 23.32 | Y23: =X23/1.1 -> 21.2 | AB23: =IF(COUNT(I23,K23,M23,O23,Q23,S23,U23,W23,Y23,AA23)=0,"N/A",MIN(I23,K23,M23,O23,Q23,S23,U23,W23,Y23,AA23)) -> 21.2 | AC23: =IF(OR(D23="",AB23="",AB23="N/A"),"N/A",D23/AB23-1) -> -0.44292453 | AD23: =IF(OR(F23="",AB23="",AB23="N/A"),"N/A",F23/AB23-1) -> -0.43241745 | AE23: HiVis: 225x450, close to 450x300 | Jaybro: 225x450, close | All Trades Group: 225x450, same SKU as 686503 | eSafety Supplies: 300x450, close | Safety Signs Australia: 300x450, close | SafetyXpress: 300x450, close | Traffic Control Products: Not found | National Safety Signs: From, shared with 686503
A24: 1.6mm Aluminium | B24: 713252 | C24: 841090 415MM 112P-LM Sign Prohibition No Smoking In This Area Metal 300x225 | D24: ='RSEA vs Quoted Comparison'!F24 -> 5.9 | E24: ='RSEA vs Quoted Comparison'!G24 -> 6.49 | F24: =IF('RSEA vs Quoted Comparison'!H24="","",'RSEA vs Quoted Comparison'!H24) -> 6.011375 | G24: =IF('RSEA vs Quoted Comparison'!I24="","",'RSEA vs Quoted Comparison'!I24) -> 6.6125125 | H24: ='RSEA vs Quoted Comparison'!D24 -> 37.99 | I24: ='RSEA vs Quoted Comparison'!E24 -> 34.536364 | J24: N/A | K24: N/A | L24: N/A | M24: N/A | N24: N/A | O24: N/A | P24: N/A | Q24: N/A | R24: N/A | S24: N/A | T24: N/A | U24: N/A | V24: N/A | W24: N/A | X24: N/A | Y24: N/A | AB24: =IF(COUNT(I24,K24,M24,O24,Q24,S24,U24,W24,Y24,AA24)=0,"N/A",MIN(I24,K24,M24,O24,Q24,S24,U24,W24,Y24,AA24)) -> 34.536364 | AC24: =IF(OR(D24="",AB24="",AB24="N/A"),"N/A",D24/AB24-1) -> -0.82916557 | AD24: =IF(OR(F24="",AB24="",AB24="N/A"),"N/A",F24/AB24-1) -> -0.82594071 | AE24: Generic site/warehouse safety sign - no comparable product found at any of the 9 researched retailers.
A25: 1.6mm Aluminium | B25: 716586 | C25: 832221 892LSM Restricted Area Auth Personnel Only Metal 450x300 | D25: ='RSEA vs Quoted Comparison'!F25 -> 11.81 | E25: ='RSEA vs Quoted Comparison'!G25 -> 12.991 | F25: =IF('RSEA vs Quoted Comparison'!H25="","",'RSEA vs Quoted Comparison'!H25) -> 12.03275 | G25: =IF('RSEA vs Quoted Comparison'!I25="","",'RSEA vs Quoted Comparison'!I25) -> 13.236025 | H25: ='RSEA vs Quoted Comparison'!D25 -> 49.99 | I25: ='RSEA vs Quoted Comparison'!E25 -> 45.445455 | J25: N/A | K25: N/A | L25: N/A | M25: N/A | N25: 42.5 | O25: =N25/1.1 -> 38.636364 | P25: 24.2 | Q25: 22 | R25: 33.5 | S25: =R25/1.1 -> 30.454545 | T25: 34.46 | U25: =T25/1.1 -> 31.327273 | V25: =W25*1.1 -> 24.75 | W25: 22.5 | X25: 10.29 | Y25: =X25/1.1 -> 9.3545455 | AB25: =IF(COUNT(I25,K25,M25,O25,Q25,S25,U25,W25,Y25,AA25)=0,"N/A",MIN(I25,K25,M25,O25,Q25,S25,U25,W25,Y25,AA25)) -> 9.3545455 | AC25: =IF(OR(D25="",AB25="",AB25="N/A"),"N/A",D25/AB25-1) -> 0.26248785 | AD25: =IF(OR(F25="",AB25="",AB25="N/A"),"N/A",F25/AB25-1) -> 0.28629981 | AE25: Jaybro: Found differently-worded 'No Entry Authorised Prohibition' 600x450 $39.58inc/$35.98ex - size differs, see notes | All Trades Group: 450x300 exact size option available | eSafety Supplies: 300x450, 600x450 also stocked | Safety Signs Australia: 450x600, size differs | SafetyXpress: range 33.19-35.73, no exact 450x300 | Traffic Control Products: 450x300 exact, poly | National Safety Signs: From, R2543 'Restricted Area Do Not Enter'
